{
    DataVersion: 3465,
    size: [7, 9, 7],
    data: [
        {pos: [0, 0, 0], state: "minecraft:cobbled_deepslate"},
        {pos: [0, 0, 1], state: "minecraft:cobbled_deepslate"},
        {pos: [0, 0, 2], state: "minecraft:cobbled_deepslate"},
        {pos: [0, 0, 3], state: "minecraft:cobbled_deepslate"},
        {pos: [0, 0, 4], state: "minecraft:cobbled_deepslate"},
        {pos: [0, 0, 5], state: "minecraft:cobbled_deepslate"},
        {pos: [0, 0, 6], state: "minecraft:cobbled_deepslate"},
        {pos: [1, 0, 0], state: "minecraft:cobbled_deepslate"},
        {pos: [1, 0, 1], state: "minecraft:cobbled_deepslate"},
        {pos: [1, 0, 2], state: "minecraft:cobbled_deepslate"},
        {pos: [1, 0, 3], state: "minecraft:cobbled_deepslate"},
        {pos: [1, 0, 4], state: "minecraft:cobbled_deepslate"},
        {pos: [1, 0, 5], state: "minecraft:cobbled_deepslate"},
        {pos: [1, 0, 6], state: "minecraft:cobbled_deepslate"},
        {pos: [2, 0, 0], state: "minecraft:cobbled_deepslate"},
        {pos: [2, 0, 1], state: "minecraft:cobbled_deepslate"},
        {pos: [2, 0, 2], state: "minecraft:cobbled_deepslate"},
        {pos: [2, 0, 3], state: "minecraft:tnt{unstable:false}"},
        {pos: [2, 0, 4], state: "minecraft:cobbled_deepslate"},
        {pos: [2, 0, 5], state: "minecraft:cobbled_deepslate"},
        {pos: [2, 0, 6], state: "minecraft:cobbled_deepslate"},
        {pos: [3, 0, 0], state: "minecraft:cobbled_deepslate"},
        {pos: [3, 0, 1], state: "minecraft:cobbled_deepslate"},
        {pos: [3, 0, 2], state: "minecraft:tnt{unstable:false}"},
        {pos: [3, 0, 3], state: "minecraft:cobbled_deepslate"},
        {pos: [3, 0, 4], state: "minecraft:tnt{unstable:false}"},
        {pos: [3, 0, 5], state: "minecraft:cobbled_deepslate"},
        {pos: [3, 0, 6], state: "minecraft:cobbled_deepslate"},
        {pos: [4, 0, 0], state: "minecraft:cobbled_deepslate"},
        {pos: [4, 0, 1], state: "minecraft:cobbled_deepslate"},
        {pos: [4, 0, 2], state: "minecraft:cobbled_deepslate"},
        {pos: [4, 0, 3], state: "minecraft:tnt{unstable:false}"},
        {pos: [4, 0, 4], state: "minecraft:cobbled_deepslate"},
        {pos: [4, 0, 5], state: "minecraft:cobbled_deepslate"},
        {pos: [4, 0, 6], state: "minecraft:cobbled_deepslate"},
        {pos: [5, 0, 0], state: "minecraft:cobbled_deepslate"},
        {pos: [5, 0, 1], state: "minecraft:cobbled_deepslate"},
        {pos: [5, 0, 2], state: "minecraft:cobbled_deepslate"},
        {pos: [5, 0, 3], state: "minecraft:cobbled_deepslate"},
        {pos: [5, 0, 4], state: "minecraft:cobbled_deepslate"},
        {pos: [5, 0, 5], state: "minecraft:cobbled_deepslate"},
        {pos: [5, 0, 6], state: "minecraft:cobbled_deepslate"},
        {pos: [6, 0, 0], state: "minecraft:cobbled_deepslate"},
        {pos: [6, 0, 1], state: "minecraft:cobbled_deepslate"},
        {pos: [6, 0, 2], state: "minecraft:cobbled_deepslate"},
        {pos: [6, 0, 3], state: "minecraft:cobbled_deepslate"},
        {pos: [6, 0, 4], state: "minecraft:cobbled_deepslate"},
        {pos: [6, 0, 5], state: "minecraft:cobbled_deepslate"},
        {pos: [6, 0, 6], state: "minecraft:cobbled_deepslate"},
        {pos: [0, 1, 0], state: "minecraft:cobbled_deepslate"},
        {pos: [0, 1, 1], state: "minecraft:cobbled_deepslate"},
        {pos: [0, 1, 2], state: "minecraft:cobbled_deepslate"},
        {pos: [0, 1, 3], state: "minecraft:sticky_piston{extended:false,facing:east}"},
        {pos: [0, 1, 4], state: "minecraft:cobbled_deepslate"},
        {pos: [0, 1, 5], state: "minecraft:cobbled_deepslate"},
        {pos: [0, 1, 6], state: "minecraft:cobbled_deepslate"},
        {pos: [1, 1, 0], state: "minecraft:cobbled_deepslate"},
        {pos: [1, 1, 1], state: "minecraft:cobbled_deepslate"},
        {pos: [1, 1, 2], state: "minecraft:cobbled_deepslate"},
        {pos: [1, 1, 3], state: "minecraft:redstone_block"},
        {pos: [1, 1, 4], state: "minecraft:cobbled_deepslate"},
        {pos: [1, 1, 5], state: "minecraft:cobbled_deepslate"},
        {pos: [1, 1, 6], state: "minecraft:cobbled_deepslate"},
        {pos: [2, 1, 0], state: "minecraft:cobbled_deepslate"},
        {pos: [2, 1, 1], state: "minecraft:cobbled_deepslate"},
        {pos: [2, 1, 2], state: "minecraft:redstone_wire{east:side,north:side,power:0,south:side,west:side}"},
        {pos: [2, 1, 3], state: "minecraft:air"},
        {pos: [2, 1, 4], state: "minecraft:redstone_wire{east:side,north:side,power:0,south:side,west:side}"},
        {pos: [2, 1, 5], state: "minecraft:cobbled_deepslate"},
        {pos: [2, 1, 6], state: "minecraft:cobbled_deepslate"},
        {pos: [3, 1, 0], state: "minecraft:sticky_piston{extended:false,facing:south}"},
        {pos: [3, 1, 1], state: "minecraft:redstone_block"},
        {pos: [3, 1, 2], state: "minecraft:air"},
        {pos: [3, 1, 3], state: "minecraft:tnt{unstable:false}"},
        {pos: [3, 1, 4], state: "minecraft:air"},
        {pos: [3, 1, 5], state: "minecraft:redstone_block"},
        {pos: [3, 1, 6], state: "minecraft:sticky_piston{extended:false,facing:north}"},
        {pos: [4, 1, 0], state: "minecraft:cobbled_deepslate"},
        {pos: [4, 1, 1], state: "minecraft:cobbled_deepslate"},
        {pos: [4, 1, 2], state: "minecraft:redstone_wire{east:side,north:side,power:0,south:side,west:side}"},
        {pos: [4, 1, 3], state: "minecraft:air"},
        {pos: [4, 1, 4], state: "minecraft:redstone_wire{east:side,north:side,power:0,south:side,west:side}"},
        {pos: [4, 1, 5], state: "minecraft:cobbled_deepslate"},
        {pos: [4, 1, 6], state: "minecraft:cobbled_deepslate"},
        {pos: [5, 1, 0], state: "minecraft:cobbled_deepslate"},
        {pos: [5, 1, 1], state: "minecraft:cobbled_deepslate"},
        {pos: [5, 1, 2], state: "minecraft:cobbled_deepslate"},
        {pos: [5, 1, 3], state: "minecraft:redstone_block"},
        {pos: [5, 1, 4], state: "minecraft:cobbled_deepslate"},
        {pos: [5, 1, 5], state: "minecraft:cobbled_deepslate"},
        {pos: [5, 1, 6], state: "minecraft:cobbled_deepslate"},
        {pos: [6, 1, 0], state: "minecraft:cobbled_deepslate"},
        {pos: [6, 1, 1], state: "minecraft:cobbled_deepslate"},
        {pos: [6, 1, 2], state: "minecraft:cobbled_deepslate"},
        {pos: [6, 1, 3], state: "minecraft:sticky_piston{extended:false,facing:west}"},
        {pos: [6, 1, 4], state: "minecraft:cobbled_deepslate"},
        {pos: [6, 1, 5], state: "minecraft:cobbled_deepslate"},
        {pos: [6, 1, 6], state: "minecraft:cobbled_deepslate"},
        {pos: [0, 2, 0], state: "minecraft:cobbled_deepslate"},
        {pos: [0, 2, 1], state: "minecraft:cobbled_deepslate"},
        {pos: [0, 2, 2], state: "minecraft:cobbled_deepslate"},
        {pos: [0, 2, 3], state: "minecraft:cobbled_deepslate"},
        {pos: [0, 2, 4], state: "minecraft:cobbled_deepslate"},
        {pos: [0, 2, 5], state: "minecraft:cobbled_deepslate"},
        {pos: [0, 2, 6], state: "minecraft:cobbled_deepslate"},
        {pos: [1, 2, 0], state: "minecraft:cobbled_deepslate"},
        {pos: [1, 2, 1], state: "minecraft:cobbled_deepslate"},
        {pos: [1, 2, 2], state: "minecraft:cobbled_deepslate"},
        {pos: [1, 2, 3], state: "minecraft:cobbled_deepslate"},
        {pos: [1, 2, 4], state: "minecraft:cobbled_deepslate"},
        {pos: [1, 2, 5], state: "minecraft:cobbled_deepslate"},
        {pos: [1, 2, 6], state: "minecraft:cobbled_deepslate"},
        {pos: [2, 2, 0], state: "minecraft:cobbled_deepslate"},
        {pos: [2, 2, 1], state: "minecraft:cobbled_deepslate"},
        {pos: [2, 2, 2], state: "minecraft:cobbled_deepslate"},
        {pos: [2, 2, 3], state: "minecraft:cobbled_deepslate"},
        {pos: [2, 2, 4], state: "minecraft:cobbled_deepslate"},
        {pos: [2, 2, 5], state: "minecraft:cobbled_deepslate"},
        {pos: [2, 2, 6], state: "minecraft:cobbled_deepslate"},
        {pos: [3, 2, 0], state: "minecraft:cobbled_deepslate"},
        {pos: [3, 2, 1], state: "minecraft:cobbled_deepslate"},
        {pos: [3, 2, 2], state: "minecraft:cobbled_deepslate"},
        {pos: [3, 2, 3], state: "minecraft:cobbled_deepslate"},
        {pos: [3, 2, 4], state: "minecraft:cobbled_deepslate"},
        {pos: [3, 2, 5], state: "minecraft:cobbled_deepslate"},
        {pos: [3, 2, 6], state: "minecraft:cobbled_deepslate"},
        {pos: [4, 2, 0], state: "minecraft:cobbled_deepslate"},
        {pos: [4, 2, 1], state: "minecraft:cobbled_deepslate"},
        {pos: [4, 2, 2], state: "minecraft:cobbled_deepslate"},
        {pos: [4, 2, 3], state: "minecraft:cobbled_deepslate"},
        {pos: [4, 2, 4], state: "minecraft:cobbled_deepslate"},
        {pos: [4, 2, 5], state: "minecraft:cobbled_deepslate"},
        {pos: [4, 2, 6], state: "minecraft:cobbled_deepslate"},
        {pos: [5, 2, 0], state: "minecraft:cobbled_deepslate"},
        {pos: [5, 2, 1], state: "minecraft:cobbled_deepslate"},
        {pos: [5, 2, 2], state: "minecraft:cobbled_deepslate"},
        {pos: [5, 2, 3], state: "minecraft:cobbled_deepslate"},
        {pos: [5, 2, 4], state: "minecraft:cobbled_deepslate"},
        {pos: [5, 2, 5], state: "minecraft:cobbled_deepslate"},
        {pos: [5, 2, 6], state: "minecraft:cobbled_deepslate"},
        {pos: [6, 2, 0], state: "minecraft:cobbled_deepslate"},
        {pos: [6, 2, 1], state: "minecraft:cobbled_deepslate"},
        {pos: [6, 2, 2], state: "minecraft:cobbled_deepslate"},
        {pos: [6, 2, 3], state: "minecraft:cobbled_deepslate"},
        {pos: [6, 2, 4], state: "minecraft:cobbled_deepslate"},
        {pos: [6, 2, 5], state: "minecraft:cobbled_deepslate"},
        {pos: [6, 2, 6], state: "minecraft:cobbled_deepslate"},
        {pos: [0, 3, 0], state: "minecraft:cobbled_deepslate"},
        {pos: [0, 3, 1], state: "minecraft:cobbled_deepslate"},
        {pos: [0, 3, 2], state: "minecraft:cobbled_deepslate"},
        {pos: [0, 3, 3], state: "minecraft:trapped_chest{facing:east,type:single,waterlogged:false}", nbt: {CustomName: '{"translate":"block.minecraft.chest"}', LootTable: "cavestone:chests/spawner", id: "minecraft:trapped_chest"}},
        {pos: [0, 3, 4], state: "packessentials:infested_deepslate_bricks"},
        {pos: [0, 3, 5], state: "minecraft:deepslate_bricks"},
        {pos: [0, 3, 6], state: "minecraft:deepslate_bricks"},
        {pos: [1, 3, 0], state: "minecraft:cobbled_deepslate"},
        {pos: [1, 3, 1], state: "minecraft:air"},
        {pos: [1, 3, 2], state: "minecraft:air"},
        {pos: [1, 3, 3], state: "minecraft:air"},
        {pos: [1, 3, 4], state: "minecraft:air"},
        {pos: [1, 3, 5], state: "minecraft:air"},
        {pos: [1, 3, 6], state: "packessentials:infested_deepslate_bricks"},
        {pos: [2, 3, 0], state: "minecraft:cobbled_deepslate"},
        {pos: [2, 3, 1], state: "minecraft:air"},
        {pos: [2, 3, 2], state: "minecraft:air"},
        {pos: [2, 3, 3], state: "minecraft:air"},
        {pos: [2, 3, 4], state: "minecraft:air"},
        {pos: [2, 3, 5], state: "minecraft:air"},
        {pos: [2, 3, 6], state: "minecraft:cobbled_deepslate"},
        {pos: [3, 3, 0], state: "minecraft:trapped_chest{facing:south,type:single,waterlogged:false}", nbt: {CustomName: '{"translate":"block.minecraft.chest"}', LootTable: "cavestone:chests/spawner", id: "minecraft:trapped_chest"}},
        {pos: [3, 3, 1], state: "minecraft:air"},
        {pos: [3, 3, 2], state: "minecraft:air"},
        {pos: [3, 3, 3], state: "minecraft:spawner", nbt: {Delay: 0s, MaxNearbyEntities: 2s, MaxSpawnDelay: 32400s, MinSpawnDelay: 21600s, RequiredPlayerRange: 16s, SpawnCount: 2s, SpawnData: {entity: {}}, SpawnPotentials: [{data: {entity: {id: "minecraft:axolotl"}}, weight: 5}, {data: {entity: {id: "minecraft:camel"}}, weight: 5}, {data: {entity: {id: "minecraft:cat"}}, weight: 4}, {data: {entity: {id: "minecraft:chicken"}}, weight: 100}, {data: {entity: {id: "minecraft:cow"}}, weight: 50}, {data: {entity: {id: "minecraft:donkey"}}, weight: 2}, {data: {entity: {id: "minecraft:fox"}}, weight: 5}, {data: {entity: {id: "minecraft:frog"}}, weight: 7}, {data: {entity: {id: "minecraft:goat"}}, weight: 5}, {data: {entity: {id: "minecraft:mule"}}, weight: 2}, {data: {entity: {id: "minecraft:ocelot"}}, weight: 3}, {data: {entity: {id: "minecraft:parrot"}}, weight: 5}, {data: {entity: {id: "minecraft:pig"}}, weight: 40}, {data: {entity: {id: "minecraft:rabbit"}}, weight: 8}, {data: {entity: {id: "minecraft:sheep"}}, weight: 50}, {data: {entity: {id: "minecraft:wolf"}}, weight: 5}], SpawnRange: 4s, id: "minecraft:mob_spawner"}},
        {pos: [3, 3, 4], state: "minecraft:air"},
        {pos: [3, 3, 5], state: "minecraft:air"},
        {pos: [3, 3, 6], state: "minecraft:trapped_chest{facing:north,type:single,waterlogged:false}", nbt: {CustomName: '{"translate":"block.minecraft.chest"}', LootTable: "cavestone:chests/spawner", id: "minecraft:trapped_chest"}},
        {pos: [4, 3, 0], state: "minecraft:cobbled_deepslate"},
        {pos: [4, 3, 1], state: "minecraft:air"},
        {pos: [4, 3, 2], state: "minecraft:air"},
        {pos: [4, 3, 3], state: "minecraft:air"},
        {pos: [4, 3, 4], state: "minecraft:air"},
        {pos: [4, 3, 5], state: "minecraft:air"},
        {pos: [4, 3, 6], state: "minecraft:cobbled_deepslate"},
        {pos: [5, 3, 0], state: "minecraft:cobbled_deepslate"},
        {pos: [5, 3, 1], state: "minecraft:air"},
        {pos: [5, 3, 2], state: "minecraft:air"},
        {pos: [5, 3, 3], state: "minecraft:air"},
        {pos: [5, 3, 4], state: "minecraft:air"},
        {pos: [5, 3, 5], state: "minecraft:air"},
        {pos: [5, 3, 6], state: "minecraft:cobbled_deepslate"},
        {pos: [6, 3, 0], state: "minecraft:cobbled_deepslate"},
        {pos: [6, 3, 1], state: "packessentials:infested_deepslate_bricks"},
        {pos: [6, 3, 2], state: "minecraft:cobbled_deepslate"},
        {pos: [6, 3, 3], state: "minecraft:trapped_chest{facing:west,type:single,waterlogged:false}", nbt: {CustomName: '{"translate":"block.minecraft.chest"}', LootTable: "cavestone:chests/spawner", id: "minecraft:trapped_chest"}},
        {pos: [6, 3, 4], state: "minecraft:cobbled_deepslate"},
        {pos: [6, 3, 5], state: "minecraft:deepslate_bricks"},
        {pos: [6, 3, 6], state: "packessentials:infested_deepslate_bricks"},
        {pos: [0, 4, 0], state: "minecraft:cobbled_deepslate"},
        {pos: [0, 4, 1], state: "packessentials:infested_deepslate_bricks"},
        {pos: [0, 4, 2], state: "minecraft:cobbled_deepslate"},
        {pos: [0, 4, 3], state: "minecraft:cobbled_deepslate_stairs{facing:west,half:top,shape:straight,waterlogged:false}"},
        {pos: [0, 4, 4], state: "minecraft:cobbled_deepslate"},
        {pos: [0, 4, 5], state: "minecraft:cobbled_deepslate"},
        {pos: [0, 4, 6], state: "minecraft:deepslate_bricks"},
        {pos: [1, 4, 0], state: "minecraft:cobbled_deepslate"},
        {pos: [1, 4, 1], state: "minecraft:air"},
        {pos: [1, 4, 2], state: "minecraft:air"},
        {pos: [1, 4, 3], state: "minecraft:air"},
        {pos: [1, 4, 4], state: "minecraft:air"},
        {pos: [1, 4, 5], state: "minecraft:air"},
        {pos: [1, 4, 6], state: "packessentials:infested_deepslate_bricks"},
        {pos: [2, 4, 0], state: "minecraft:cobbled_deepslate"},
        {pos: [2, 4, 1], state: "minecraft:air"},
        {pos: [2, 4, 2], state: "minecraft:air"},
        {pos: [2, 4, 3], state: "minecraft:air"},
        {pos: [2, 4, 4], state: "minecraft:air"},
        {pos: [2, 4, 5], state: "minecraft:air"},
        {pos: [2, 4, 6], state: "minecraft:cobbled_deepslate"},
        {pos: [3, 4, 0], state: "minecraft:cobbled_deepslate_stairs{facing:north,half:top,shape:straight,waterlogged:false}"},
        {pos: [3, 4, 1], state: "minecraft:air"},
        {pos: [3, 4, 2], state: "minecraft:air"},
        {pos: [3, 4, 3], state: "minecraft:air"},
        {pos: [3, 4, 4], state: "minecraft:air"},
        {pos: [3, 4, 5], state: "minecraft:air"},
        {pos: [3, 4, 6], state: "minecraft:cobbled_deepslate_stairs{facing:south,half:top,shape:straight,waterlogged:false}"},
        {pos: [4, 4, 0], state: "minecraft:cobbled_deepslate"},
        {pos: [4, 4, 1], state: "minecraft:air"},
        {pos: [4, 4, 2], state: "minecraft:air"},
        {pos: [4, 4, 3], state: "minecraft:air"},
        {pos: [4, 4, 4], state: "minecraft:air"},
        {pos: [4, 4, 5], state: "minecraft:air"},
        {pos: [4, 4, 6], state: "minecraft:cobbled_deepslate"},
        {pos: [5, 4, 0], state: "minecraft:deepslate_bricks"},
        {pos: [5, 4, 1], state: "minecraft:air"},
        {pos: [5, 4, 2], state: "minecraft:air"},
        {pos: [5, 4, 3], state: "minecraft:air"},
        {pos: [5, 4, 4], state: "minecraft:air"},
        {pos: [5, 4, 5], state: "minecraft:air"},
        {pos: [5, 4, 6], state: "packessentials:infested_deepslate_bricks"},
        {pos: [6, 4, 0], state: "packessentials:infested_deepslate_bricks"},
        {pos: [6, 4, 1], state: "minecraft:deepslate_bricks"},
        {pos: [6, 4, 2], state: "minecraft:cobbled_deepslate"},
        {pos: [6, 4, 3], state: "minecraft:cobbled_deepslate_stairs{facing:east,half:top,shape:straight,waterlogged:false}"},
        {pos: [6, 4, 4], state: "minecraft:cobbled_deepslate"},
        {pos: [6, 4, 5], state: "minecraft:cobbled_deepslate"},
        {pos: [6, 4, 6], state: "minecraft:deepslate_bricks"},
        {pos: [0, 5, 0], state: "minecraft:deepslate_bricks"},
        {pos: [0, 5, 1], state: "packessentials:infested_deepslate_bricks"},
        {pos: [0, 5, 2], state: "minecraft:cobbled_deepslate"},
        {pos: [0, 5, 4], state: "minecraft:cobbled_deepslate"},
        {pos: [0, 5, 5], state: "minecraft:cobbled_deepslate"},
        {pos: [0, 5, 6], state: "minecraft:cobbled_deepslate"},
        {pos: [1, 5, 0], state: "packessentials:infested_deepslate_bricks"},
        {pos: [1, 5, 1], state: "minecraft:air"},
        {pos: [1, 5, 2], state: "minecraft:air"},
        {pos: [1, 5, 3], state: "minecraft:soul_wall_torch{facing:east}"},
        {pos: [1, 5, 4], state: "minecraft:air"},
        {pos: [1, 5, 5], state: "minecraft:air"},
        {pos: [1, 5, 6], state: "minecraft:cobbled_deepslate"},
        {pos: [2, 5, 0], state: "minecraft:cobbled_deepslate"},
        {pos: [2, 5, 1], state: "minecraft:air"},
        {pos: [2, 5, 2], state: "minecraft:air"},
        {pos: [2, 5, 3], state: "minecraft:air"},
        {pos: [2, 5, 4], state: "minecraft:air"},
        {pos: [2, 5, 5], state: "minecraft:air"},
        {pos: [2, 5, 6], state: "minecraft:cobbled_deepslate"},
        {pos: [3, 5, 1], state: "minecraft:soul_wall_torch{facing:south}"},
        {pos: [3, 5, 2], state: "minecraft:air"},
        {pos: [3, 5, 3], state: "minecraft:air"},
        {pos: [3, 5, 4], state: "minecraft:air"},
        {pos: [3, 5, 5], state: "minecraft:soul_wall_torch{facing:north}"},
        {pos: [4, 5, 0], state: "minecraft:cobbled_deepslate"},
        {pos: [4, 5, 1], state: "minecraft:air"},
        {pos: [4, 5, 2], state: "minecraft:air"},
        {pos: [4, 5, 3], state: "minecraft:air"},
        {pos: [4, 5, 4], state: "minecraft:air"},
        {pos: [4, 5, 5], state: "minecraft:air"},
        {pos: [4, 5, 6], state: "minecraft:cobbled_deepslate"},
        {pos: [5, 5, 0], state: "minecraft:deepslate_bricks"},
        {pos: [5, 5, 1], state: "minecraft:air"},
        {pos: [5, 5, 2], state: "minecraft:air"},
        {pos: [5, 5, 3], state: "minecraft:soul_wall_torch{facing:west}"},
        {pos: [5, 5, 4], state: "minecraft:air"},
        {pos: [5, 5, 5], state: "minecraft:air"},
        {pos: [5, 5, 6], state: "minecraft:cobbled_deepslate"},
        {pos: [6, 5, 0], state: "minecraft:cobbled_deepslate"},
        {pos: [6, 5, 1], state: "minecraft:cobbled_deepslate"},
        {pos: [6, 5, 2], state: "minecraft:cobbled_deepslate"},
        {pos: [6, 5, 4], state: "minecraft:cobbled_deepslate"},
        {pos: [6, 5, 5], state: "packessentials:infested_deepslate_bricks"},
        {pos: [6, 5, 6], state: "packessentials:infested_deepslate_bricks"},
        {pos: [0, 6, 0], state: "minecraft:cobbled_deepslate"},
        {pos: [0, 6, 1], state: "minecraft:cobbled_deepslate"},
        {pos: [0, 6, 5], state: "minecraft:cobbled_deepslate"},
        {pos: [0, 6, 6], state: "minecraft:cobbled_deepslate"},
        {pos: [1, 6, 0], state: "minecraft:cobbled_deepslate"},
        {pos: [1, 6, 1], state: "minecraft:air"},
        {pos: [1, 6, 2], state: "minecraft:air"},
        {pos: [1, 6, 3], state: "minecraft:air"},
        {pos: [1, 6, 4], state: "minecraft:air"},
        {pos: [1, 6, 5], state: "minecraft:air"},
        {pos: [1, 6, 6], state: "minecraft:cobbled_deepslate"},
        {pos: [2, 6, 1], state: "minecraft:air"},
        {pos: [2, 6, 2], state: "minecraft:air"},
        {pos: [2, 6, 3], state: "minecraft:air"},
        {pos: [2, 6, 4], state: "minecraft:air"},
        {pos: [2, 6, 5], state: "minecraft:air"},
        {pos: [3, 6, 1], state: "minecraft:air"},
        {pos: [3, 6, 2], state: "minecraft:air"},
        {pos: [3, 6, 3], state: "minecraft:air"},
        {pos: [3, 6, 4], state: "minecraft:air"},
        {pos: [3, 6, 5], state: "minecraft:air"},
        {pos: [4, 6, 1], state: "minecraft:air"},
        {pos: [4, 6, 2], state: "minecraft:air"},
        {pos: [4, 6, 3], state: "minecraft:air"},
        {pos: [4, 6, 4], state: "minecraft:air"},
        {pos: [4, 6, 5], state: "minecraft:air"},
        {pos: [5, 6, 0], state: "minecraft:cobbled_deepslate"},
        {pos: [5, 6, 1], state: "minecraft:air"},
        {pos: [5, 6, 2], state: "minecraft:air"},
        {pos: [5, 6, 3], state: "minecraft:air"},
        {pos: [5, 6, 4], state: "minecraft:air"},
        {pos: [5, 6, 5], state: "minecraft:air"},
        {pos: [5, 6, 6], state: "minecraft:cobbled_deepslate"},
        {pos: [6, 6, 0], state: "minecraft:cobbled_deepslate"},
        {pos: [6, 6, 1], state: "minecraft:cobbled_deepslate"},
        {pos: [6, 6, 5], state: "minecraft:cobbled_deepslate"},
        {pos: [6, 6, 6], state: "minecraft:cobbled_deepslate"},
        {pos: [0, 7, 0], state: "minecraft:cobbled_deepslate"},
        {pos: [0, 7, 6], state: "minecraft:cobbled_deepslate"},
        {pos: [1, 7, 1], state: "minecraft:air"},
        {pos: [1, 7, 2], state: "minecraft:air"},
        {pos: [1, 7, 3], state: "minecraft:air"},
        {pos: [1, 7, 4], state: "minecraft:air"},
        {pos: [1, 7, 5], state: "minecraft:air"},
        {pos: [2, 7, 1], state: "minecraft:air"},
        {pos: [2, 7, 2], state: "minecraft:air"},
        {pos: [2, 7, 3], state: "minecraft:air"},
        {pos: [2, 7, 4], state: "minecraft:air"},
        {pos: [2, 7, 5], state: "minecraft:air"},
        {pos: [3, 7, 1], state: "minecraft:air"},
        {pos: [3, 7, 2], state: "minecraft:air"},
        {pos: [3, 7, 3], state: "minecraft:air"},
        {pos: [3, 7, 4], state: "minecraft:air"},
        {pos: [3, 7, 5], state: "minecraft:air"},
        {pos: [4, 7, 1], state: "minecraft:air"},
        {pos: [4, 7, 2], state: "minecraft:air"},
        {pos: [4, 7, 3], state: "minecraft:air"},
        {pos: [4, 7, 4], state: "minecraft:air"},
        {pos: [4, 7, 5], state: "minecraft:air"},
        {pos: [5, 7, 1], state: "minecraft:air"},
        {pos: [5, 7, 2], state: "minecraft:air"},
        {pos: [5, 7, 3], state: "minecraft:air"},
        {pos: [5, 7, 4], state: "minecraft:air"},
        {pos: [5, 7, 5], state: "minecraft:air"},
        {pos: [6, 7, 0], state: "minecraft:cobbled_deepslate"},
        {pos: [6, 7, 6], state: "minecraft:cobbled_deepslate"}
    ],
    entities: [],
    palette: [
        "minecraft:cobbled_deepslate",
        "minecraft:tnt{unstable:false}",
        "minecraft:sticky_piston{extended:false,facing:east}",
        "minecraft:redstone_block",
        "minecraft:sticky_piston{extended:false,facing:south}",
        "minecraft:sticky_piston{extended:false,facing:north}",
        "minecraft:sticky_piston{extended:false,facing:west}",
        "packessentials:infested_deepslate_bricks",
        "minecraft:deepslate_bricks",
        "minecraft:redstone_wire{east:side,north:side,power:0,south:side,west:side}",
        "minecraft:air",
        "minecraft:cobbled_deepslate_stairs{facing:west,half:top,shape:straight,waterlogged:false}",
        "minecraft:cobbled_deepslate_stairs{facing:north,half:top,shape:straight,waterlogged:false}",
        "minecraft:cobbled_deepslate_stairs{facing:south,half:top,shape:straight,waterlogged:false}",
        "minecraft:cobbled_deepslate_stairs{facing:east,half:top,shape:straight,waterlogged:false}",
        "minecraft:soul_wall_torch{facing:east}",
        "minecraft:soul_wall_torch{facing:south}",
        "minecraft:soul_wall_torch{facing:north}",
        "minecraft:soul_wall_torch{facing:west}",
        "minecraft:trapped_chest{facing:east,type:single,waterlogged:false}",
        "minecraft:trapped_chest{facing:south,type:single,waterlogged:false}",
        "minecraft:spawner",
        "minecraft:trapped_chest{facing:north,type:single,waterlogged:false}",
        "minecraft:trapped_chest{facing:west,type:single,waterlogged:false}"
    ]
}